WARNING: Phonon needs QCoreApplication::applicationName to be set to export audio output names through the DBUS interface 
Exception in thread Thread-2:
Traceback (most recent call last):
  File "/usr/lib/python2.6/threading.py", line 532, in __bootstrap_inner
    self.run()
  File "/usr/lib/python2.6/threading.py", line 736, in run
    self.function(*self.args, **self.kwargs)
TypeError: 'NoneType' object is not callable

Exception in thread Thread-21:
Traceback (most recent call last):
  File "/usr/lib/python2.6/threading.py", line 532, in __bootstrap_inner
    self.run()
  File "/usr/lib/python2.6/threading.py", line 736, in run
    self.function(*self.args, **self.kwargs)
TypeError: 'NoneType' object is not callable

Exception in thread Thread-14:
Traceback (most recent call last):
  File "/usr/lib/python2.6/threading.py", line 532, in __bootstrap_inner
    self.run()
  File "/usr/lib/python2.6/threading.py", line 736, in run
    self.function(*self.args, **self.kwargs)
TypeError: 'NoneType' object is not callable

Exception in thread Thread-5:
Traceback (most recent call last):
  File "/usr/lib/python2.6/threading.py", line 532, in __bootstrap_inner
    self.run()
  File "/usr/lib/python2.6/threading.py", line 736, in run
    self.function(*self.args, **self.kwargs)
TypeError: 'NoneType' object is not callable

Exception in thread Thread-10:
Traceback (most recent call last):
  File "/usr/lib/python2.6/threading.py", line 532, in __bootstrap_inner
    self.run()
  File "/usr/lib/python2.6/threading.py", line 736, in run
    self.function(*self.args, **self.kwargs)
TypeError: 'NoneType' object is not callable

Exception in thread Thread-35:
Traceback (most recent call last):
  File "/usr/lib/python2.6/threading.py", line 532, in __bootstrap_inner
    self.run()
  File "/usr/lib/python2.6/threading.py", line 736, in run
    self.function(*self.args, **self.kwargs)
TypeError: 'NoneType' object is not callable

Exception in thread Thread-16:
Traceback (most recent call last):
  File "/usr/lib/python2.6/threading.py", line 532, in __bootstrap_inner
    self.run()
  File "/usr/lib/python2.6/threading.py", line 736, in run
    self.function(*self.args, **self.kwargs)
TypeError: 'NoneType' object is not callable

Exception in thread Thread-9:
Traceback (most recent call last):
  File "/usr/lib/python2.6/threading.py", line 532, in __bootstrap_inner
    self.run()
  File "/usr/lib/python2.6/threading.py", line 736, in run
    self.function(*self.args, **self.kwargs)
TypeError: 'NoneType' object is not callable

Exception in thread Thread-26:
Traceback (most recent call last):
  File "/usr/lib/python2.6/threading.py", line 532, in __bootstrap_inner
    self.run()
  File "/usr/lib/python2.6/threading.py", line 736, in run
    self.function(*self.args, **self.kwargs)
TypeError: 'NoneType' object is not callable

Exception in thread Thread-17:
Traceback (most recent call last):
  File "/usr/lib/python2.6/threading.py", line 532, in __bootstrap_inner
    self.run()
  File "/usr/lib/python2.6/threading.py", line 736, in run
    self.function(*self.args, **self.kwargs)
TypeError: 'NoneType' object is not callable

Exception in thread Thread-18:
Traceback (most recent call last):
  File "/usr/lib/python2.6/threading.py", line 532, in __bootstrap_inner
    self.run()
  File "/usr/lib/python2.6/threading.py", line 736, in run
    self.function(*self.args, **self.kwargs)
TypeError: 'NoneType' object is not callable

Exception in thread Thread-39:
Traceback (most recent call last):
  File "/usr/lib/python2.6/threading.py", line 532, in __bootstrap_inner
    self.run()
  File "/usr/lib/python2.6/threading.py", line 736, in run
    self.function(*self.args, **self.kwargs)
TypeError: 'NoneType' object is not callable

Exception in thread Thread-15:
Traceback (most recent call last):
  File "/usr/lib/python2.6/threading.py", line 532, in __bootstrap_inner
    self.run()
  File "/usr/lib/python2.6/threading.py", line 736, in run
    self.function(*self.args, **self.kwargs)
TypeError: 'NoneType' object is not callable

Exception in thread Thread-29:
Traceback (most recent call last):
  File "/usr/lib/python2.6/threading.py", line 532, in __bootstrap_inner
    self.run()
  File "/usr/lib/python2.6/threading.py", line 736, in run
    self.function(*self.args, **self.kwargs)
TypeError: 'NoneType' object is not callable

Exception in thread Thread-43:
Traceback (most recent call last):
  File "/usr/lib/python2.6/threading.py", line 532, in __bootstrap_inner
    self.run()
  File "/usr/lib/python2.6/threading.py", line 736, in run
    self.function(*self.args, **self.kwargs)
TypeError: 'NoneType' object is not callable

Exception in thread Thread-23:
Traceback (most recent call last):
  File "/usr/lib/python2.6/threading.py", line 532, in __bootstrap_inner
    self.run()
  File "/usr/lib/python2.6/threading.py", line 736, in run
    self.function(*self.args, **self.kwargs)
TypeError: 'NoneType' object is not callable

Exception in thread Thread-34:
Traceback (most recent call last):
  File "/usr/lib/python2.6/threading.py", line 532, in __bootstrap_inner
    self.run()
  File "/usr/lib/python2.6/threading.py", line 736, in run
    self.function(*self.args, **self.kwargs)
TypeError: 'NoneType' object is not callable

Exception in thread Thread-7:
Traceback (most recent call last):
  File "/usr/lib/python2.6/threading.py", line 532, in __bootstrap_inner
    self.run()
  File "/usr/lib/python2.6/threading.py", line 736, in run
    self.function(*self.args, **self.kwargs)
TypeError: 'NoneType' object is not callable

Exception in thread Thread-8:
Traceback (most recent call last):
  File "/usr/lib/python2.6/threading.py", line 532, in __bootstrap_inner
    self.run()
  File "/usr/lib/python2.6/threading.py", line 736, in run
    self.function(*self.args, **self.kwargs)
TypeError: 'NoneType' object is not callable

Exception in thread Thread-56:
Traceback (most recent call last):
  File "/usr/lib/python2.6/threading.py", line 532, in __bootstrap_inner
    self.run()
  File "/usr/lib/python2.6/threading.py", line 736, in run
    self.function(*self.args, **self.kwargs)
TypeError: 'NoneType' object is not callable

Exception in thread Thread-19:
Traceback (most recent call last):
  File "/usr/lib/python2.6/threading.py", line 532, in __bootstrap_inner
    self.run()
  File "/usr/lib/python2.6/threading.py", line 736, in run
    self.function(*self.args, **self.kwargs)
TypeError: 'NoneType' object is not callable

Exception in thread Thread-28:
Traceback (most recent call last):
  File "/usr/lib/python2.6/threading.py", line 532, in __bootstrap_inner
    self.run()
  File "/usr/lib/python2.6/threading.py", line 736, in run
    self.function(*self.args, **self.kwargs)
TypeError: 'NoneType' object is not callable

Exception in thread Thread-37:
Traceback (most recent call last):
  File "/usr/lib/python2.6/threading.py", line 532, in __bootstrap_inner
    self.run()
  File "/usr/lib/python2.6/threading.py", line 736, in run
    self.function(*self.args, **self.kwargs)
TypeError: 'NoneType' object is not callable

Exception in thread Thread-30:
Traceback (most recent call last):
  File "/usr/lib/python2.6/threading.py", line 532, in __bootstrap_inner
    self.run()
  File "/usr/lib/python2.6/threading.py", line 736, in run
    self.function(*self.args, **self.kwargs)
TypeError: 'NoneType' object is not callable

Exception in thread Thread-1:
Traceback (most recent call last):
  File "/usr/lib/python2.6/threading.py", line 532, in __bootstrap_inner
    self.run()
  File "/usr/lib/python2.6/threading.py", line 736, in run
    self.function(*self.args, **self.kwargs)
TypeError: 'NoneType' object is not callable

Exception in thread Thread-25:
Traceback (most recent call last):
  File "/usr/lib/python2.6/threading.py", line 532, in __bootstrap_inner
    self.run()
  File "/usr/lib/python2.6/threading.py", line 736, in run
    self.function(*self.args, **self.kwargs)
TypeError: 'NoneType' object is not callable

Exception in thread Thread-44:
Traceback (most recent call last):
  File "/usr/lib/python2.6/threading.py", line 532, in __bootstrap_inner
    self.run()
  File "/usr/lib/python2.6/threading.py", line 736, in run
    self.function(*self.args, **self.kwargs)
TypeError: 'NoneType' object is not callable

Exception in thread Thread-4:
Traceback (most recent call last):
  File "/usr/lib/python2.6/threading.py", line 532, in __bootstrap_inner
    self.run()
  File "/usr/lib/python2.6/threading.py", line 736, in run
    self.function(*self.args, **self.kwargs)
TypeError: 'NoneType' object is not callable

Exception in thread Thread-33:
Traceback (most recent call last):
  File "/usr/lib/python2.6/threading.py", line 532, in __bootstrap_inner
    self.run()
  File "/usr/lib/python2.6/threading.py", line 736, in run
    self.function(*self.args, **self.kwargs)
TypeError: 'NoneType' object is not callable

Exception in thread Thread-36:
Traceback (most recent call last):
  File "/usr/lib/python2.6/threading.py", line 532, in __bootstrap_inner
    self.run()
  File "/usr/lib/python2.6/threading.py", line 736, in run
    self.function(*self.args, **self.kwargs)
TypeError: 'NoneType' object is not callable

Exception in thread Thread-41:
Traceback (most recent call last):
  File "/usr/lib/python2.6/threading.py", line 532, in __bootstrap_inner
    self.run()
  File "/usr/lib/python2.6/threading.py", line 736, in run
    self.function(*self.args, **self.kwargs)
TypeError: 'NoneType' object is not callable

Exception in thread Thread-69:
Traceback (most recent call last):
  File "/usr/lib/python2.6/threading.py", line 532, in __bootstrap_inner
    self.run()
  File "/usr/lib/python2.6/threading.py", line 736, in run
    self.function(*self.args, **self.kwargs)
TypeError: 'NoneType' object is not callable

Exception in thread Thread-13:
Traceback (most recent call last):
  File "/usr/lib/python2.6/threading.py", line 532, in __bootstrap_inner
    self.run()
  File "/usr/lib/python2.6/threading.py", line 736, in run
    self.function(*self.args, **self.kwargs)
TypeError: 'NoneType' object is not callable

Exception in thread Thread-38:
Traceback (most recent call last):
  File "/usr/lib/python2.6/threading.py", line 532, in __bootstrap_inner
    self.run()
  File "/usr/lib/python2.6/threading.py", line 736, in run
    self.function(*self.args, **self.kwargs)
TypeError: 'NoneType' object is not callable

Exception in thread Thread-66:
Traceback (most recent call last):
  File "/usr/lib/python2.6/threading.py", line 532, in __bootstrap_inner
    self.run()
  File "/usr/lib/python2.6/threading.py", line 736, in run
    self.function(*self.args, **self.kwargs)
TypeError: 'NoneType' object is not callable

Exception in thread Thread-55:
Traceback (most recent call last):
  File "/usr/lib/python2.6/threading.py", line 532, in __bootstrap_inner
    self.run()
  File "/usr/lib/python2.6/threading.py", line 736, in run
    self.function(*self.args, **self.kwargs)
TypeError: 'NoneType' object is not callable

Exception in thread Thread-47:
Traceback (most recent call last):
  File "/usr/lib/python2.6/threading.py", line 532, in __bootstrap_inner
    self.run()
  File "/usr/lib/python2.6/threading.py", line 736, in run
    self.function(*self.args, **self.kwargs)
TypeError: 'NoneType' object is not callable

Exception in thread Thread-22:
Traceback (most recent call last):
  File "/usr/lib/python2.6/threading.py", line 532, in __bootstrap_inner
    self.run()
  File "/usr/lib/python2.6/threading.py", line 736, in run
    self.function(*self.args, **self.kwargs)
TypeError: 'NoneType' object is not callable

Exception in thread Thread-57:
Traceback (most recent call last):
  File "/usr/lib/python2.6/threading.py", line 532, in __bootstrap_inner
    self.run()
  File "/usr/lib/python2.6/threading.py", line 736, in run
    self.function(*self.args, **self.kwargs)
TypeError: 'NoneType' object is not callable

Exception in thread Thread-20:
Traceback (most recent call last):
  File "/usr/lib/python2.6/threading.py", line 532, in __bootstrap_inner
    self.run()
  File "/usr/lib/python2.6/threading.py", line 736, in run
    self.function(*self.args, **self.kwargs)
TypeError: 'NoneType' object is not callable

Exception in thread Thread-24:
Traceback (most recent call last):
  File "/usr/lib/python2.6/threading.py", line 532, in __bootstrap_inner
    self.run()
  File "/usr/lib/python2.6/threading.py", line 736, in run
    self.function(*self.args, **self.kwargs)
TypeError: 'NoneType' object is not callable

Exception in thread Thread-12:
Traceback (most recent call last):
  File "/usr/lib/python2.6/threading.py", line 532, in __bootstrap_inner
    self.run()
  File "/usr/lib/python2.6/threading.py", line 736, in run
    self.function(*self.args, **self.kwargs)
TypeError: 'NoneType' object is not callable

Exception in thread Thread-71:
Traceback (most recent call last):
  File "/usr/lib/python2.6/threading.py", line 532, in __bootstrap_inner
    self.run()
  File "/usr/lib/python2.6/threading.py", line 736, in run
    self.function(*self.args, **self.kwargs)
TypeError: 'NoneType' object is not callable

Exception in thread Thread-62:
Traceback (most recent call last):
  File "/usr/lib/python2.6/threading.py", line 532, in __bootstrap_inner
    self.run()
  File "/usr/lib/python2.6/threading.py", line 736, in run
    self.function(*self.args, **self.kwargs)
TypeError: 'NoneType' object is not callable

Exception in thread Thread-63:
Traceback (most recent call last):
  File "/usr/lib/python2.6/threading.py", line 532, in __bootstrap_inner
    self.run()
  File "/usr/lib/python2.6/threading.py", line 736, in run
    self.function(*self.args, **self.kwargs)
TypeError: 'NoneType' object is not callable

Exception in thread Thread-59:
Traceback (most recent call last):
  File "/usr/lib/python2.6/threading.py", line 532, in __bootstrap_inner
    self.run()
  File "/usr/lib/python2.6/threading.py", line 736, in run
    self.function(*self.args, **self.kwargs)
TypeError: 'NoneType' object is not callable

Exception in thread Thread-31:
Traceback (most recent call last):
  File "/usr/lib/python2.6/threading.py", line 532, in __bootstrap_inner
    self.run()
  File "/usr/lib/python2.6/threading.py", line 736, in run
    self.function(*self.args, **self.kwargs)
TypeError: 'NoneType' object is not callable

Exception in thread Thread-64:
Traceback (most recent call last):
  File "/usr/lib/python2.6/threading.py", line 532, in __bootstrap_inner
    self.run()
  File "/usr/lib/python2.6/threading.py", line 736, in run
    self.function(*self.args, **self.kwargs)
TypeError: 'NoneType' object is not callable

Exception in thread Thread-32:
Traceback (most recent call last):
  File "/usr/lib/python2.6/threading.py", line 532, in __bootstrap_inner
    self.run()
  File "/usr/lib/python2.6/threading.py", line 736, in run
    self.function(*self.args, **self.kwargs)
TypeError: 'NoneType' object is not callable

Exception in thread Thread-82:
Traceback (most recent call last):
  File "/usr/lib/python2.6/threading.py", line 532, in __bootstrap_inner
    self.run()
  File "/usr/lib/python2.6/threading.py", line 736, in run
    self.function(*self.args, **self.kwargs)
TypeError: 'NoneType' object is not callable

Exception in thread Thread-46:
Traceback (most recent call last):
  File "/usr/lib/python2.6/threading.py", line 532, in __bootstrap_inner
    self.run()
  File "/usr/lib/python2.6/threading.py", line 736, in run
    self.function(*self.args, **self.kwargs)
TypeError: 'NoneType' object is not callable

Exception in thread Thread-54:
Traceback (most recent call last):
  File "/usr/lib/python2.6/threading.py", line 532, in __bootstrap_inner
    self.run()
  File "/usr/lib/python2.6/threading.py", line 736, in run
    self.function(*self.args, **self.kwargs)
TypeError: 'NoneType' object is not callable

Exception in thread Thread-72:
Traceback (most recent call last):
  File "/usr/lib/python2.6/threading.py", line 532, in __bootstrap_inner
    self.run()
  File "/usr/lib/python2.6/threading.py", line 736, in run
    self.function(*self.args, **self.kwargs)
TypeError: 'NoneType' object is not callable

Exception in thread Thread-58:
Traceback (most recent call last):
  File "/usr/lib/python2.6/threading.py", line 532, in __bootstrap_inner
    self.run()
  File "/usr/lib/python2.6/threading.py", line 736, in run
    self.function(*self.args, **self.kwargs)
TypeError: 'NoneType' object is not callable

Exception in thread Thread-70:
Traceback (most recent call last):
  File "/usr/lib/python2.6/threading.py", line 532, in __bootstrap_inner
    self.run()
  File "/usr/lib/python2.6/threading.py", line 736, in run
    self.function(*self.args, **self.kwargs)
TypeError: 'NoneType' object is not callable

Exception in thread Thread-78:
Traceback (most recent call last):
  File "/usr/lib/python2.6/threading.py", line 532, in __bootstrap_inner
    self.run()
  File "/usr/lib/python2.6/threading.py", line 736, in run
    self.function(*self.args, **self.kwargs)
TypeError: 'NoneType' object is not callable

Exception in thread Thread-42:
Traceback (most recent call last):
  File "/usr/lib/python2.6/threading.py", line 532, in __bootstrap_inner
    self.run()
  File "/usr/lib/python2.6/threading.py", line 736, in run
    self.function(*self.args, **self.kwargs)
TypeError: 'NoneType' object is not callable

Exception in thread Thread-49:
Traceback (most recent call last):
  File "/usr/lib/python2.6/threading.py", line 532, in __bootstrap_inner
    self.run()
  File "/usr/lib/python2.6/threading.py", line 736, in run
    self.function(*self.args, **self.kwargs)
TypeError: 'NoneType' object is not callable

Exception in thread Thread-50:
Traceback (most recent call last):
  File "/usr/lib/python2.6/threading.py", line 532, in __bootstrap_inner
    self.run()
  File "/usr/lib/python2.6/threading.py", line 736, in run
    self.function(*self.args, **self.kwargs)
TypeError: 'NoneType' object is not callable

Exception in thread Thread-51:
Traceback (most recent call last):
  File "/usr/lib/python2.6/threading.py", line 532, in __bootstrap_inner
    self.run()
  File "/usr/lib/python2.6/threading.py", line 736, in run
    self.function(*self.args, **self.kwargs)
TypeError: 'NoneType' object is not callable

Exception in thread Thread-53:
Traceback (most recent call last):
  File "/usr/lib/python2.6/threading.py", line 532, in __bootstrap_inner
    self.run()
  File "/usr/lib/python2.6/threading.py", line 736, in run
    self.function(*self.args, **self.kwargs)
TypeError: 'NoneType' object is not callable

Exception in thread Thread-65:
Traceback (most recent call last):
  File "/usr/lib/python2.6/threading.py", line 532, in __bootstrap_inner
    self.run()
  File "/usr/lib/python2.6/threading.py", line 736, in run
    self.function(*self.args, **self.kwargs)
TypeError: 'NoneType' object is not callable

Exception in thread Thread-84:
Traceback (most recent call last):
  File "/usr/lib/python2.6/threading.py", line 532, in __bootstrap_inner
    self.run()
  File "/usr/lib/python2.6/threading.py", line 736, in run
    self.function(*self.args, **self.kwargs)
TypeError: 'NoneType' object is not callable

Exception in thread Thread-3:
Traceback (most recent call last):
  File "/usr/lib/python2.6/threading.py", line 532, in __bootstrap_inner
    self.run()
  File "/usr/lib/python2.6/threading.py", line 736, in run
    self.function(*self.args, **self.kwargs)
TypeError: 'NoneType' object is not callable

Exception in thread Thread-6:
Traceback (most recent call last):
  File "/usr/lib/python2.6/threading.py", line 532, in __bootstrap_inner
    self.run()
  File "/usr/lib/python2.6/threading.py", line 736, in run
    self.function(*self.args, **self.kwargs)
TypeError: 'NoneType' object is not callable

Exception in thread Thread-67:
Traceback (most recent call last):
  File "/usr/lib/python2.6/threading.py", line 532, in __bootstrap_inner
    self.run()
  File "/usr/lib/python2.6/threading.py", line 736, in run
    self.function(*self.args, **self.kwargs)
TypeError: 'NoneType' object is not callable

Exception in thread Thread-73:
Traceback (most recent call last):
  File "/usr/lib/python2.6/threading.py", line 532, in __bootstrap_inner
    self.run()
  File "/usr/lib/python2.6/threading.py", line 736, in run
    self.function(*self.args, **self.kwargs)
TypeError: 'NoneType' object is not callable

Exception in thread Thread-27:
Traceback (most recent call last):
  File "/usr/lib/python2.6/threading.py", line 532, in __bootstrap_inner
    self.run()
  File "/usr/lib/python2.6/threading.py", line 736, in run
    self.function(*self.args, **self.kwargs)
TypeError: 'NoneType' object is not callable

Exception in thread Thread-75:
Traceback (most recent call last):
  File "/usr/lib/python2.6/threading.py", line 532, in __bootstrap_inner
    self.run()
  File "/usr/lib/python2.6/threading.py", line 736, in run
    self.function(*self.args, **self.kwargs)
TypeError: 'NoneType' object is not callable

Exception in thread Thread-52:
Traceback (most recent call last):
  File "/usr/lib/python2.6/threading.py", line 532, in __bootstrap_inner
    self.run()
  File "/usr/lib/python2.6/threading.py", line 736, in run
    self.function(*self.args, **self.kwargs)
TypeError: 'NoneType' object is not callable

Exception in thread Thread-45:
Traceback (most recent call last):
  File "/usr/lib/python2.6/threading.py", line 532, in __bootstrap_inner
    self.run()
  File "/usr/lib/python2.6/threading.py", line 736, in run
    self.function(*self.args, **self.kwargs)
TypeError: 'NoneType' object is not callable

Exception in thread Thread-76:
Traceback (most recent call last):
  File "/usr/lib/python2.6/threading.py", line 532, in __bootstrap_inner
    self.run()
  File "/usr/lib/python2.6/threading.py", line 736, in run
    self.function(*self.args, **self.kwargs)
TypeError: 'NoneType' object is not callable

Exception in thread Thread-80:
Traceback (most recent call last):
  File "/usr/lib/python2.6/threading.py", line 532, in __bootstrap_inner
    self.run()
  File "/usr/lib/python2.6/threading.py", line 736, in run
    self.function(*self.args, **self.kwargs)
TypeError: 'NoneType' object is not callable

Exception in thread Thread-11:
Traceback (most recent call last):
  File "/usr/lib/python2.6/threading.py", line 532, in __bootstrap_inner
    self.run()
  File "/usr/lib/python2.6/threading.py", line 736, in run
    self.function(*self.args, **self.kwargs)
TypeError: 'NoneType' object is not callable

Exception in thread Thread-90:
Traceback (most recent call last):
  File "/usr/lib/python2.6/threading.py", line 532, in __bootstrap_inner
    self.run()
  File "/usr/lib/python2.6/threading.py", line 736, in run
    self.function(*self.args, **self.kwargs)
TypeError: 'NoneType' object is not callable

Exception in thread Thread-60:
Traceback (most recent call last):
  File "/usr/lib/python2.6/threading.py", line 532, in __bootstrap_inner
    self.run()
  File "/usr/lib/python2.6/threading.py", line 736, in run
    self.function(*self.args, **self.kwargs)
TypeError: 'NoneType' object is not callable

Exception in thread Thread-83:
Traceback (most recent call last):
  File "/usr/lib/python2.6/threading.py", line 532, in __bootstrap_inner
    self.run()
  File "/usr/lib/python2.6/threading.py", line 736, in run
    self.function(*self.args, **self.kwargs)
TypeError: 'NoneType' object is not callable

Exception in thread Thread-86:
Traceback (most recent call last):
  File "/usr/lib/python2.6/threading.py", line 532, in __bootstrap_inner
    self.run()
  File "/usr/lib/python2.6/threading.py", line 736, in run
    self.function(*self.args, **self.kwargs)
TypeError: 'NoneType' object is not callable

Exception in thread Thread-74:
Traceback (most recent call last):
  File "/usr/lib/python2.6/threading.py", line 532, in __bootstrap_inner
    self.run()
  File "/usr/lib/python2.6/threading.py", line 736, in run
    self.function(*self.args, **self.kwargs)
TypeError: 'NoneType' object is not callable

Exception in thread Thread-48:
Traceback (most recent call last):
  File "/usr/lib/python2.6/threading.py", line 532, in __bootstrap_inner
    self.run()
  File "/usr/lib/python2.6/threading.py", line 736, in run
    self.function(*self.args, **self.kwargs)
TypeError: 'NoneType' object is not callable

Exception in thread Thread-40:
Traceback (most recent call last):
  File "/usr/lib/python2.6/threading.py", line 532, in __bootstrap_inner
    self.run()
  File "/usr/lib/python2.6/threading.py", line 736, in run
    self.function(*self.args, **self.kwargs)
TypeError: 'NoneType' object is not callable

Exception in thread Thread-61:
Traceback (most recent call last):
  File "/usr/lib/python2.6/threading.py", line 532, in __bootstrap_inner
    self.run()
  File "/usr/lib/python2.6/threading.py", line 736, in run
    self.function(*self.args, **self.kwargs)
TypeError: 'NoneType' object is not callable

Exception in thread Thread-92:
Traceback (most recent call last):
  File "/usr/lib/python2.6/threading.py", line 532, in __bootstrap_inner
    self.run()
  File "/usr/lib/python2.6/threading.py", line 736, in run
    self.function(*self.args, **self.kwargs)
TypeError: 'NoneType' object is not callable

Exception in thread Thread-68:
Traceback (most recent call last):
  File "/usr/lib/python2.6/threading.py", line 532, in __bootstrap_inner
    self.run()
  File "/usr/lib/python2.6/threading.py", line 736, in run
    self.function(*self.args, **self.kwargs)
TypeError: 'NoneType' object is not callable

Exception in thread Thread-94:
Traceback (most recent call last):
  File "/usr/lib/python2.6/threading.py", line 532, in __bootstrap_inner
    self.run()
  File "/usr/lib/python2.6/threading.py", line 736, in run
    self.function(*self.args, **self.kwargs)
TypeError: 'NoneType' object is not callable

Exception in thread Thread-77:
Traceback (most recent call last):
  File "/usr/lib/python2.6/threading.py", line 532, in __bootstrap_inner
    self.run()
  File "/usr/lib/python2.6/threading.py", line 736, in run
    self.function(*self.args, **self.kwargs)
TypeError: 'NoneType' object is not callable

Exception in thread Thread-89:
Traceback (most recent call last):
  File "/usr/lib/python2.6/threading.py", line 532, in __bootstrap_inner
    self.run()
  File "/usr/lib/python2.6/threading.py", line 736, in run
    self.function(*self.args, **self.kwargs)
TypeError: 'NoneType' object is not callable

Exception in thread Thread-85:
Traceback (most recent call last):
  File "/usr/lib/python2.6/threading.py", line 532, in __bootstrap_inner
    self.run()
  File "/usr/lib/python2.6/threading.py", line 736, in run
    self.function(*self.args, **self.kwargs)
TypeError: 'NoneType' object is not callable

Exception in thread Thread-81:
Traceback (most recent call last):
  File "/usr/lib/python2.6/threading.py", line 532, in __bootstrap_inner
    self.run()
  File "/usr/lib/python2.6/threading.py", line 736, in run
    self.function(*self.args, **self.kwargs)
TypeError: 'NoneType' object is not callable

Exception in thread Thread-95:
Traceback (most recent call last):
  File "/usr/lib/python2.6/threading.py", line 532, in __bootstrap_inner
    self.run()
  File "/usr/lib/python2.6/threading.py", line 736, in run
    self.function(*self.args, **self.kwargs)
TypeError: 'NoneType' object is not callable

Exception in thread Thread-93:
Traceback (most recent call last):
  File "/usr/lib/python2.6/threading.py", line 532, in __bootstrap_inner
    self.run()
  File "/usr/lib/python2.6/threading.py", line 736, in run
    self.function(*self.args, **self.kwargs)
TypeError: 'NoneType' object is not callable

Exception in thread Thread-87:
Traceback (most recent call last):
  File "/usr/lib/python2.6/threading.py", line 532, in __bootstrap_inner
    self.run()
  File "/usr/lib/python2.6/threading.py", line 736, in run
    self.function(*self.args, **self.kwargs)
TypeError: 'NoneType' object is not callable

Exception in thread Thread-96:
Traceback (most recent call last):
  File "/usr/lib/python2.6/threading.py", line 532, in __bootstrap_inner
    self.run()
  File "/usr/lib/python2.6/threading.py", line 736, in run
    self.function(*self.args, **self.kwargs)
TypeError: 'NoneType' object is not callable

Exception in thread Thread-79:
Traceback (most recent call last):
  File "/usr/lib/python2.6/threading.py", line 532, in __bootstrap_inner
    self.run()
  File "/usr/lib/python2.6/threading.py", line 736, in run
    self.function(*self.args, **self.kwargs)
TypeError: 'NoneType' object is not callable

Exception in thread Thread-91:
Traceback (most recent call last):
  File "/usr/lib/python2.6/threading.py", line 532, in __bootstrap_inner
    self.run()
  File "/usr/lib/python2.6/threading.py", line 736, in run
    self.function(*self.args, **self.kwargs)
TypeError: 'NoneType' object is not callable

Exception in thread Thread-88:
Traceback (most recent call last):
  File "/usr/lib/python2.6/threading.py", line 532, in __bootstrap_inner
    self.run()
  File "/usr/lib/python2.6/threading.py", line 736, in run
    self.function(*self.args, **self.kwargs)
TypeError: 'NoneType' object is not callable

Exception in thread Thread-97:
Traceback (most recent call last):
  File "/usr/lib/python2.6/threading.py", line 532, in __bootstrap_inner
    self.run()
  File "/usr/lib/python2.6/threading.py", line 736, in run
    self.function(*self.args, **self.kwargs)
TypeError: 'NoneType' object is not callable

Exception in thread Thread-173:
Traceback (most recent call last):
  File "/usr/lib/python2.6/threading.py", line 532, in __bootstrap_inner
    self.run()
  File "/usr/lib/python2.6/threading.py", line 736, in run
    self.function(*self.args, **self.kwargs)
TypeError: 'NoneType' object is not callable

Exception in thread Thread-175:
Traceback (most recent call last):
  File "/usr/lib/python2.6/threading.py", line 532, in __bootstrap_inner
    self.run()
  File "/usr/lib/python2.6/threading.py", line 736, in run
    self.function(*self.args, **self.kwargs)
TypeError: 'NoneType' object is not callable

Exception in thread Thread-128:
Traceback (most recent call last):
  File "/usr/lib/python2.6/threading.py", line 532, in __bootstrap_inner
    self.run()
  File "/usr/lib/python2.6/threading.py", line 736, in run
    self.function(*self.args, **self.kwargs)
TypeError: 'NoneType' object is not callable

Exception in thread Thread-133:
Traceback (most recent call last):
  File "/usr/lib/python2.6/threading.py", line 532, in __bootstrap_inner
    self.run()
  File "/usr/lib/python2.6/threading.py", line 736, in run
    self.function(*self.args, **self.kwargs)
TypeError: 'NoneType' object is not callable

Exception in thread Thread-119:
Traceback (most recent call last):
  File "/usr/lib/python2.6/threading.py", line 532, in __bootstrap_inner
    self.run()
  File "/usr/lib/python2.6/threading.py", line 736, in run
    self.function(*self.args, **self.kwargs)
TypeError: 'NoneType' object is not callable

Exception in thread Thread-162:
Traceback (most recent call last):
  File "/usr/lib/python2.6/threading.py", line 532, in __bootstrap_inner
    self.run()
  File "/usr/lib/python2.6/threading.py", line 736, in run
    self.function(*self.args, **self.kwargs)
TypeError: 'NoneType' object is not callable

Exception in thread Thread-171:
Traceback (most recent call last):
  File "/usr/lib/python2.6/threading.py", line 532, in __bootstrap_inner
    self.run()
  File "/usr/lib/python2.6/threading.py", line 736, in run
    self.function(*self.args, **self.kwargs)
TypeError: 'NoneType' object is not callable

Exception in thread Thread-122:
Traceback (most recent call last):
  File "/usr/lib/python2.6/threading.py", line 532, in __bootstrap_inner
    self.run()
  File "/usr/lib/python2.6/threading.py", line 736, in run
    self.function(*self.args, **self.kwargs)
TypeError: 'NoneType' object is not callable

Exception in thread Thread-137:
Traceback (most recent call last):
  File "/usr/lib/python2.6/threading.py", line 532, in __bootstrap_inner
    self.run()
  File "/usr/lib/python2.6/threading.py", line 736, in run
    self.function(*self.args, **self.kwargs)
TypeError: 'NoneType' object is not callable

Exception in thread Thread-140:
Traceback (most recent call last):
  File "/usr/lib/python2.6/threading.py", line 532, in __bootstrap_inner
    self.run()
  File "/usr/lib/python2.6/threading.py", line 736, in run
    self.function(*self.args, **self.kwargs)
TypeError: 'NoneType' object is not callable

Exception in thread Thread-148:
Traceback (most recent call last):
  File "/usr/lib/python2.6/threading.py", line 532, in __bootstrap_inner
    self.run()
  File "/usr/lib/python2.6/threading.py", line 736, in run
    self.function(*self.args, **self.kwargs)
TypeError: 'NoneType' object is not callable

Exception in thread Thread-103:
Traceback (most recent call last):
  File "/usr/lib/python2.6/threading.py", line 532, in __bootstrap_inner
    self.run()
  File "/usr/lib/python2.6/threading.py", line 736, in run
    self.function(*self.args, **self.kwargs)
TypeError: 'NoneType' object is not callable

Exception in thread Thread-106:
Traceback (most recent call last):
  File "/usr/lib/python2.6/threading.py", line 532, in __bootstrap_inner
    self.run()
  File "/usr/lib/python2.6/threading.py", line 736, in run
    self.function(*self.args, **self.kwargs)
TypeError: 'NoneType' object is not callable

Exception in thread Thread-170:
Traceback (most recent call last):
  File "/usr/lib/python2.6/threading.py", line 532, in __bootstrap_inner
    self.run()
  File "/usr/lib/python2.6/threading.py", line 736, in run
    self.function(*self.args, **self.kwargs)
TypeError: 'NoneType' object is not callable

Exception in thread Thread-172:
Traceback (most recent call last):
  File "/usr/lib/python2.6/threading.py", line 532, in __bootstrap_inner
    self.run()
  File "/usr/lib/python2.6/threading.py", line 736, in run
    self.function(*self.args, **self.kwargs)
TypeError: 'NoneType' object is not callable

Exception in thread Thread-124:
Traceback (most recent call last):
  File "/usr/lib/python2.6/threading.py", line 532, in __bootstrap_inner
    self.run()
  File "/usr/lib/python2.6/threading.py", line 736, in run
    self.function(*self.args, **self.kwargs)
TypeError: 'NoneType' object is not callable

Exception in thread Thread-156:
Traceback (most recent call last):
  File "/usr/lib/python2.6/threading.py", line 532, in __bootstrap_inner
    self.run()
  File "/usr/lib/python2.6/threading.py", line 736, in run
    self.function(*self.args, **self.kwargs)
TypeError: 'NoneType' object is not callable

Exception in thread Thread-163:
Traceback (most recent call last):
  File "/usr/lib/python2.6/threading.py", line 532, in __bootstrap_inner
    self.run()
  File "/usr/lib/python2.6/threading.py", line 736, in run
    self.function(*self.args, **self.kwargs)
TypeError: 'NoneType' object is not callable

Exception in thread Thread-143:
Traceback (most recent call last):
  File "/usr/lib/python2.6/threading.py", line 532, in __bootstrap_inner
    self.run()
  File "/usr/lib/python2.6/threading.py", line 736, in run
    self.function(*self.args, **self.kwargs)
TypeError: 'NoneType' object is not callable

Exception in thread Thread-139:
Traceback (most recent call last):
  File "/usr/lib/python2.6/threading.py", line 532, in __bootstrap_inner
    self.run()
  File "/usr/lib/python2.6/threading.py", line 736, in run
    self.function(*self.args, **self.kwargs)
TypeError: 'NoneType' object is not callable

Exception in thread Thread-99:
Traceback (most recent call last):
  File "/usr/lib/python2.6/threading.py", line 532, in __bootstrap_inner
    self.run()
  File "/usr/lib/python2.6/threading.py", line 736, in run
    self.function(*self.args, **self.kwargs)
TypeError: 'NoneType' object is not callable

Exception in thread Thread-101:
Traceback (most recent call last):
  File "/usr/lib/python2.6/threading.py", line 532, in __bootstrap_inner
    self.run()
  File "/usr/lib/python2.6/threading.py", line 736, in run
    self.function(*self.args, **self.kwargs)
TypeError: 'NoneType' object is not callable

Exception in thread Thread-102:
Traceback (most recent call last):
  File "/usr/lib/python2.6/threading.py", line 532, in __bootstrap_inner
    self.run()
  File "/usr/lib/python2.6/threading.py", line 736, in run
    self.function(*self.args, **self.kwargs)
TypeError: 'NoneType' object is not callable

Exception in thread Thread-110:
Traceback (most recent call last):
  File "/usr/lib/python2.6/threading.py", line 532, in __bootstrap_inner
    self.run()
  File "/usr/lib/python2.6/threading.py", line 736, in run
    self.function(*self.args, **self.kwargs)
TypeError: 'NoneType' object is not callable

Exception in thread Thread-113:
Traceback (most recent call last):
  File "/usr/lib/python2.6/threading.py", line 532, in __bootstrap_inner
    self.run()
  File "/usr/lib/python2.6/threading.py", line 736, in run
    self.function(*self.args, **self.kwargs)
TypeError: 'NoneType' object is not callable

Exception in thread Thread-116:
Traceback (most recent call last):
  File "/usr/lib/python2.6/threading.py", line 532, in __bootstrap_inner
    self.run()
  File "/usr/lib/python2.6/threading.py", line 736, in run
    self.function(*self.args, **self.kwargs)
TypeError: 'NoneType' object is not callable

Exception in thread Thread-178:
Traceback (most recent call last):
  File "/usr/lib/python2.6/threading.py", line 532, in __bootstrap_inner
    self.run()
  File "/usr/lib/python2.6/threading.py", line 736, in run
    self.function(*self.args, **self.kwargs)
TypeError: 'NoneType' object is not callable

Exception in thread Thread-168:
Traceback (most recent call last):
  File "/usr/lib/python2.6/threading.py", line 532, in __bootstrap_inner
    self.run()
  File "/usr/lib/python2.6/threading.py", line 736, in run
    self.function(*self.args, **self.kwargs)
TypeError: 'NoneType' object is not callable

Exception in thread Thread-169:
Traceback (most recent call last):
  File "/usr/lib/python2.6/threading.py", line 532, in __bootstrap_inner
    self.run()
  File "/usr/lib/python2.6/threading.py", line 736, in run
    self.function(*self.args, **self.kwargs)
TypeError: 'NoneType' object is not callable

Exception in thread Thread-120:
Traceback (most recent call last):
  File "/usr/lib/python2.6/threading.py", line 532, in __bootstrap_inner
    self.run()
  File "/usr/lib/python2.6/threading.py", line 736, in run
    self.function(*self.args, **self.kwargs)
TypeError: 'NoneType' object is not callable

Exception in thread Thread-129:
Traceback (most recent call last):
  File "/usr/lib/python2.6/threading.py", line 532, in __bootstrap_inner
    self.run()
  File "/usr/lib/python2.6/threading.py", line 736, in run
    self.function(*self.args, **self.kwargs)
TypeError: 'NoneType' object is not callable

Exception in thread Thread-159:
Traceback (most recent call last):
  File "/usr/lib/python2.6/threading.py", line 532, in __bootstrap_inner
    self.run()
  File "/usr/lib/python2.6/threading.py", line 736, in run
    self.function(*self.args, **self.kwargs)
TypeError: 'NoneType' object is not callable

Exception in thread Thread-131:
Traceback (most recent call last):
  File "/usr/lib/python2.6/threading.py", line 532, in __bootstrap_inner
    self.run()
  File "/usr/lib/python2.6/threading.py", line 736, in run
    self.function(*self.args, **self.kwargs)
TypeError: 'NoneType' object is not callable

Exception in thread Thread-138:
Traceback (most recent call last):
  File "/usr/lib/python2.6/threading.py", line 532, in __bootstrap_inner
    self.run()
  File "/usr/lib/python2.6/threading.py", line 736, in run
    self.function(*self.args, **self.kwargs)
TypeError: 'NoneType' object is not callable

Exception in thread Thread-98:
Traceback (most recent call last):
  File "/usr/lib/python2.6/threading.py", line 532, in __bootstrap_inner
    self.run()
  File "/usr/lib/python2.6/threading.py", line 736, in run
    self.function(*self.args, **self.kwargs)
TypeError: 'NoneType' object is not callable

Exception in thread Thread-145:
Traceback (most recent call last):
  File "/usr/lib/python2.6/threading.py", line 532, in __bootstrap_inner
    self.run()
  File "/usr/lib/python2.6/threading.py", line 736, in run
    self.function(*self.args, **self.kwargs)
TypeError: 'NoneType' object is not callable

Exception in thread Thread-176:
Traceback (most recent call last):
  File "/usr/lib/python2.6/threading.py", line 532, in __bootstrap_inner
    self.run()
  File "/usr/lib/python2.6/threading.py", line 736, in run
    self.function(*self.args, **self.kwargs)
TypeError: 'NoneType' object is not callable

Exception in thread Thread-150:
Traceback (most recent call last):
  File "/usr/lib/python2.6/threading.py", line 532, in __bootstrap_inner
    self.run()
  File "/usr/lib/python2.6/threading.py", line 736, in run
    self.function(*self.args, **self.kwargs)
TypeError: 'NoneType' object is not callable

Exception in thread Thread-108:
Traceback (most recent call last):
  File "/usr/lib/python2.6/threading.py", line 532, in __bootstrap_inner
    self.run()
  File "/usr/lib/python2.6/threading.py", line 736, in run
    self.function(*self.args, **self.kwargs)
TypeError: 'NoneType' object is not callable

Exception in thread Thread-111:
Traceback (most recent call last):
  File "/usr/lib/python2.6/threading.py", line 532, in __bootstrap_inner
    self.run()
  File "/usr/lib/python2.6/threading.py", line 736, in run
    self.function(*self.args, **self.kwargs)
TypeError: 'NoneType' object is not callable

Exception in thread Thread-177:
Traceback (most recent call last):
  File "/usr/lib/python2.6/threading.py", line 532, in __bootstrap_inner
    self.run()
  File "/usr/lib/python2.6/threading.py", line 736, in run
    self.function(*self.args, **self.kwargs)
TypeError: 'NoneType' object is not callable

Exception in thread Thread-181:
Traceback (most recent call last):
  File "/usr/lib/python2.6/threading.py", line 532, in __bootstrap_inner
    self.run()
  File "/usr/lib/python2.6/threading.py", line 736, in run
    self.function(*self.args, **self.kwargs)
TypeError: 'NoneType' object is not callable

Exception in thread Thread-183:
Traceback (most recent call last):
  File "/usr/lib/python2.6/threading.py", line 532, in __bootstrap_inner
    self.run()
  File "/usr/lib/python2.6/threading.py", line 736, in run
    self.function(*self.args, **self.kwargs)
TypeError: 'NoneType' object is not callable

Exception in thread Thread-155:
Traceback (most recent call last):
  File "/usr/lib/python2.6/threading.py", line 532, in __bootstrap_inner
    self.run()
  File "/usr/lib/python2.6/threading.py", line 736, in run
    self.function(*self.args, **self.kwargs)
TypeError: 'NoneType' object is not callable

Exception in thread Thread-161:
Traceback (most recent call last):
  File "/usr/lib/python2.6/threading.py", line 532, in __bootstrap_inner
    self.run()
  File "/usr/lib/python2.6/threading.py", line 736, in run
    self.function(*self.args, **self.kwargs)
TypeError: 'NoneType' object is not callable

Exception in thread Thread-165:
Traceback (most recent call last):
  File "/usr/lib/python2.6/threading.py", line 532, in __bootstrap_inner
    self.run()
  File "/usr/lib/python2.6/threading.py", line 736, in run
    self.function(*self.args, **self.kwargs)
TypeError: 'NoneType' object is not callable

Exception in thread Thread-142:
Traceback (most recent call last):
  File "/usr/lib/python2.6/threading.py", line 532, in __bootstrap_inner
    self.run()
  File "/usr/lib/python2.6/threading.py", line 736, in run
    self.function(*self.args, **self.kwargs)
TypeError: 'NoneType' object is not callable

Exception in thread Thread-151:
Traceback (most recent call last):
  File "/usr/lib/python2.6/threading.py", line 532, in __bootstrap_inner
    self.run()
  File "/usr/lib/python2.6/threading.py", line 736, in run
    self.function(*self.args, **self.kwargs)
TypeError: 'NoneType' object is not callable

Exception in thread Thread-112:
Traceback (most recent call last):
  File "/usr/lib/python2.6/threading.py", line 532, in __bootstrap_inner
    self.run()
  File "/usr/lib/python2.6/threading.py", line 736, in run
    self.function(*self.args, **self.kwargs)
TypeError: 'NoneType' object is not callable

Exception in thread Thread-115:
Traceback (most recent call last):
  File "/usr/lib/python2.6/threading.py", line 532, in __bootstrap_inner
    self.run()
  File "/usr/lib/python2.6/threading.py", line 736, in run
    self.function(*self.args, **self.kwargs)
TypeError: 'NoneType' object is not callable

Exception in thread Thread-180:
Traceback (most recent call last):
  File "/usr/lib/python2.6/threading.py", line 532, in __bootstrap_inner
    self.run()
  File "/usr/lib/python2.6/threading.py", line 736, in run
    self.function(*self.args, **self.kwargs)
TypeError: 'NoneType' object is not callable

Exception in thread Thread-174:
Traceback (most recent call last):
  File "/usr/lib/python2.6/threading.py", line 532, in __bootstrap_inner
    self.run()
  File "/usr/lib/python2.6/threading.py", line 736, in run
    self.function(*self.args, **self.kwargs)
TypeError: 'NoneType' object is not callable

Exception in thread Thread-125:
Traceback (most recent call last):
  File "/usr/lib/python2.6/threading.py", line 532, in __bootstrap_inner
    self.run()
  File "/usr/lib/python2.6/threading.py", line 736, in run
    self.function(*self.args, **self.kwargs)
TypeError: 'NoneType' object is not callable

Exception in thread Thread-132:
Traceback (most recent call last):
  File "/usr/lib/python2.6/threading.py", line 532, in __bootstrap_inner
    self.run()
  File "/usr/lib/python2.6/threading.py", line 736, in run
    self.function(*self.args, **self.kwargs)
TypeError: 'NoneType' object is not callable

Exception in thread Thread-134:
Traceback (most recent call last):
  File "/usr/lib/python2.6/threading.py", line 532, in __bootstrap_inner
    self.run()
  File "/usr/lib/python2.6/threading.py", line 736, in run
    self.function(*self.args, **self.kwargs)
TypeError: 'NoneType' object is not callable

Exception in thread Thread-164:
Traceback (most recent call last):
  File "/usr/lib/python2.6/threading.py", line 532, in __bootstrap_inner
    self.run()
  File "/usr/lib/python2.6/threading.py", line 736, in run
    self.function(*self.args, **self.kwargs)
TypeError: 'NoneType' object is not callable

Exception in thread Thread-167:
Traceback (most recent call last):
  File "/usr/lib/python2.6/threading.py", line 532, in __bootstrap_inner
    self.run()
  File "/usr/lib/python2.6/threading.py", line 736, in run
    self.function(*self.args, **self.kwargs)
TypeError: 'NoneType' object is not callable

Exception in thread Thread-146:
Traceback (most recent call last):
  File "/usr/lib/python2.6/threading.py", line 532, in __bootstrap_inner
    self.run()
  File "/usr/lib/python2.6/threading.py", line 736, in run
    self.function(*self.args, **self.kwargs)
TypeError: 'NoneType' object is not callable

Exception in thread Thread-149:
Traceback (most recent call last):
  File "/usr/lib/python2.6/threading.py", line 532, in __bootstrap_inner
    self.run()
  File "/usr/lib/python2.6/threading.py", line 736, in run
    self.function(*self.args, **self.kwargs)
TypeError: 'NoneType' object is not callable

Exception in thread Thread-107:
Traceback (most recent call last):
  File "/usr/lib/python2.6/threading.py", line 532, in __bootstrap_inner
    self.run()
  File "/usr/lib/python2.6/threading.py", line 736, in run
    self.function(*self.args, **self.kwargs)
TypeError: 'NoneType' object is not callable

Exception in thread Thread-118:
Traceback (most recent call last):
  File "/usr/lib/python2.6/threading.py", line 532, in __bootstrap_inner
    self.run()
  File "/usr/lib/python2.6/threading.py", line 736, in run
    self.function(*self.args, **self.kwargs)
TypeError: 'NoneType' object is not callable

Exception in thread Thread-154:
Traceback (most recent call last):
  File "/usr/lib/python2.6/threading.py", line 532, in __bootstrap_inner
    self.run()
  File "/usr/lib/python2.6/threading.py", line 736, in run
    self.function(*self.args, **self.kwargs)
TypeError: 'NoneType' object is not callable

Exception in thread Thread-126:
Traceback (most recent call last):
  File "/usr/lib/python2.6/threading.py", line 532, in __bootstrap_inner
    self.run()
  File "/usr/lib/python2.6/threading.py", line 736, in run
    self.function(*self.args, **self.kwargs)
TypeError: 'NoneType' object is not callable

Exception in thread Thread-130:
Traceback (most recent call last):
  File "/usr/lib/python2.6/threading.py", line 532, in __bootstrap_inner
    self.run()
  File "/usr/lib/python2.6/threading.py", line 736, in run
    self.function(*self.args, **self.kwargs)
TypeError: 'NoneType' object is not callable

Exception in thread Thread-135:
Traceback (most recent call last):
  File "/usr/lib/python2.6/threading.py", line 532, in __bootstrap_inner
    self.run()
  File "/usr/lib/python2.6/threading.py", line 736, in run
    self.function(*self.args, **self.kwargs)
TypeError: 'NoneType' object is not callable

Exception in thread Thread-136:
Traceback (most recent call last):
  File "/usr/lib/python2.6/threading.py", line 532, in __bootstrap_inner
    self.run()
  File "/usr/lib/python2.6/threading.py", line 736, in run
    self.function(*self.args, **self.kwargs)
TypeError: 'NoneType' object is not callable

Exception in thread Thread-147:
Traceback (most recent call last):
  File "/usr/lib/python2.6/threading.py", line 532, in __bootstrap_inner
    self.run()
  File "/usr/lib/python2.6/threading.py", line 736, in run
    self.function(*self.args, **self.kwargs)
TypeError: 'NoneType' object is not callable

Exception in thread Thread-152:
Traceback (most recent call last):
  File "/usr/lib/python2.6/threading.py", line 532, in __bootstrap_inner
    self.run()
  File "/usr/lib/python2.6/threading.py", line 736, in run
    self.function(*self.args, **self.kwargs)
TypeError: 'NoneType' object is not callable

Exception in thread Thread-104:
Traceback (most recent call last):
  File "/usr/lib/python2.6/threading.py", line 532, in __bootstrap_inner
    self.run()
  File "/usr/lib/python2.6/threading.py", line 736, in run
    self.function(*self.args, **self.kwargs)
TypeError: 'NoneType' object is not callable

Exception in thread Thread-105:
Traceback (most recent call last):
  File "/usr/lib/python2.6/threading.py", line 532, in __bootstrap_inner
    self.run()
  File "/usr/lib/python2.6/threading.py", line 736, in run
    self.function(*self.args, **self.kwargs)
TypeError: 'NoneType' object is not callable

Exception in thread Thread-114:
Traceback (most recent call last):
  File "/usr/lib/python2.6/threading.py", line 532, in __bootstrap_inner
    self.run()
  File "/usr/lib/python2.6/threading.py", line 736, in run
    self.function(*self.args, **self.kwargs)
TypeError: 'NoneType' object is not callable

Exception in thread Thread-166:
Traceback (most recent call last):
  File "/usr/lib/python2.6/threading.py", line 532, in __bootstrap_inner
    self.run()
  File "/usr/lib/python2.6/threading.py", line 736, in run
    self.function(*self.args, **self.kwargs)
TypeError: 'NoneType' object is not callable

Exception in thread Thread-182:
Traceback (most recent call last):
  File "/usr/lib/python2.6/threading.py", line 532, in __bootstrap_inner
    self.run()
  File "/usr/lib/python2.6/threading.py", line 736, in run
    self.function(*self.args, **self.kwargs)
TypeError: 'NoneType' object is not callable

Exception in thread Thread-127:
Traceback (most recent call last):
  File "/usr/lib/python2.6/threading.py", line 532, in __bootstrap_inner
    self.run()
  File "/usr/lib/python2.6/threading.py", line 736, in run
    self.function(*self.args, **self.kwargs)
TypeError: 'NoneType' object is not callable

Exception in thread Thread-141:
Traceback (most recent call last):
  File "/usr/lib/python2.6/threading.py", line 532, in __bootstrap_inner
    self.run()
  File "/usr/lib/python2.6/threading.py", line 736, in run
    self.function(*self.args, **self.kwargs)
TypeError: 'NoneType' object is not callable

Exception in thread Thread-153:
Traceback (most recent call last):
  File "/usr/lib/python2.6/threading.py", line 532, in __bootstrap_inner
    self.run()
  File "/usr/lib/python2.6/threading.py", line 736, in run
    self.function(*self.args, **self.kwargs)
TypeError: 'NoneType' object is not callable

Exception in thread Thread-109:
Traceback (most recent call last):
  File "/usr/lib/python2.6/threading.py", line 532, in __bootstrap_inner
    self.run()
  File "/usr/lib/python2.6/threading.py", line 736, in run
    self.function(*self.args, **self.kwargs)
TypeError: 'NoneType' object is not callable

Exception in thread Thread-117:
Traceback (most recent call last):
  File "/usr/lib/python2.6/threading.py", line 532, in __bootstrap_inner
    self.run()
  File "/usr/lib/python2.6/threading.py", line 736, in run
    self.function(*self.args, **self.kwargs)
TypeError: 'NoneType' object is not callable

Exception in thread Thread-179:
Traceback (most recent call last):
  File "/usr/lib/python2.6/threading.py", line 532, in __bootstrap_inner
    self.run()
  File "/usr/lib/python2.6/threading.py", line 736, in run
    self.function(*self.args, **self.kwargs)
TypeError: 'NoneType' object is not callable

Exception in thread Thread-123:
Traceback (most recent call last):
  File "/usr/lib/python2.6/threading.py", line 532, in __bootstrap_inner
    self.run()
  File "/usr/lib/python2.6/threading.py", line 736, in run
    self.function(*self.args, **self.kwargs)
TypeError: 'NoneType' object is not callable

Exception in thread Thread-158:
Traceback (most recent call last):
  File "/usr/lib/python2.6/threading.py", line 532, in __bootstrap_inner
    self.run()
  File "/usr/lib/python2.6/threading.py", line 736, in run
    self.function(*self.args, **self.kwargs)
TypeError: 'NoneType' object is not callable

Exception in thread Thread-160:
Traceback (most recent call last):
  File "/usr/lib/python2.6/threading.py", line 532, in __bootstrap_inner
    self.run()
  File "/usr/lib/python2.6/threading.py", line 736, in run
    self.function(*self.args, **self.kwargs)
TypeError: 'NoneType' object is not callable

Exception in thread Thread-121:
Traceback (most recent call last):
  File "/usr/lib/python2.6/threading.py", line 532, in __bootstrap_inner
    self.run()
  File "/usr/lib/python2.6/threading.py", line 736, in run
    self.function(*self.args, **self.kwargs)
TypeError: 'NoneType' object is not callable

Exception in thread Thread-144:
Traceback (most recent call last):
  File "/usr/lib/python2.6/threading.py", line 532, in __bootstrap_inner
    self.run()
  File "/usr/lib/python2.6/threading.py", line 736, in run
    self.function(*self.args, **self.kwargs)
TypeError: 'NoneType' object is not callable

Exception in thread Thread-157:
Traceback (most recent call last):
  File "/usr/lib/python2.6/threading.py", line 532, in __bootstrap_inner
    self.run()
  File "/usr/lib/python2.6/threading.py", line 736, in run
    self.function(*self.args, **self.kwargs)
TypeError: 'NoneType' object is not callable

Exception in thread Thread-100:
Traceback (most recent call last):
  File "/usr/lib/python2.6/threading.py", line 532, in __bootstrap_inner
    self.run()
  File "/usr/lib/python2.6/threading.py", line 736, in run
    self.function(*self.args, **self.kwargs)
TypeError: 'NoneType' object is not callable

Exception in thread Thread-184:
Traceback (most recent call last):
  File "/usr/lib/python2.6/threading.py", line 532, in __bootstrap_inner
    self.run()
  File "/usr/lib/python2.6/threading.py", line 736, in run
    self.function(*self.args, **self.kwargs)
TypeError: 'NoneType' object is not callable

Exception in thread Thread-185:
Traceback (most recent call last):
  File "/usr/lib/python2.6/threading.py", line 532, in __bootstrap_inner
    self.run()
  File "/usr/lib/python2.6/threading.py", line 736, in run
    self.function(*self.args, **self.kwargs)
TypeError: 'NoneType' object is not callable

Exception in thread Thread-186:
Traceback (most recent call last):
  File "/usr/lib/python2.6/threading.py", line 532, in __bootstrap_inner
    self.run()
  File "/usr/lib/python2.6/threading.py", line 736, in run
    self.function(*self.args, **self.kwargs)
TypeError: 'NoneType' object is not callable

Exception in thread Thread-188:
Traceback (most recent call last):
  File "/usr/lib/python2.6/threading.py", line 532, in __bootstrap_inner
    self.run()
  File "/usr/lib/python2.6/threading.py", line 736, in run
    self.function(*self.args, **self.kwargs)
TypeError: 'NoneType' object is not callable

Exception in thread Thread-187:
Traceback (most recent call last):
  File "/usr/lib/python2.6/threading.py", line 532, in __bootstrap_inner
    self.run()
  File "/usr/lib/python2.6/threading.py", line 736, in run
    self.function(*self.args, **self.kwargs)
TypeError: 'NoneType' object is not callable

Exception in thread Thread-189:
Traceback (most recent call last):
  File "/usr/lib/python2.6/threading.py", line 532, in __bootstrap_inner
    self.run()
  File "/usr/lib/python2.6/threading.py", line 736, in run
    self.function(*self.args, **self.kwargs)
TypeError: 'NoneType' object is not callable

Exception in thread Thread-191:
Traceback (most recent call last):
  File "/usr/lib/python2.6/threading.py", line 532, in __bootstrap_inner
    self.run()
  File "/usr/lib/python2.6/threading.py", line 736, in run
    self.function(*self.args, **self.kwargs)
TypeError: 'NoneType' object is not callable

Exception in thread Thread-192:
Traceback (most recent call last):
  File "/usr/lib/python2.6/threading.py", line 532, in __bootstrap_inner
    self.run()
  File "/usr/lib/python2.6/threading.py", line 736, in run
    self.function(*self.args, **self.kwargs)
TypeError: 'NoneType' object is not callable

Exception in thread Thread-194:
Traceback (most recent call last):
  File "/usr/lib/python2.6/threading.py", line 532, in __bootstrap_inner
    self.run()
  File "/usr/lib/python2.6/threading.py", line 736, in run
    self.function(*self.args, **self.kwargs)
TypeError: 'NoneType' object is not callable

Exception in thread Thread-193:
Traceback (most recent call last):
  File "/usr/lib/python2.6/threading.py", line 532, in __bootstrap_inner
    self.run()
  File "/usr/lib/python2.6/threading.py", line 736, in run
    self.function(*self.args, **self.kwargs)
TypeError: 'NoneType' object is not callable

Exception in thread Thread-196:
Traceback (most recent call last):
  File "/usr/lib/python2.6/threading.py", line 532, in __bootstrap_inner
    self.run()
  File "/usr/lib/python2.6/threading.py", line 736, in run
    self.function(*self.args, **self.kwargs)
TypeError: 'NoneType' object is not callable

Exception in thread Thread-197:
Traceback (most recent call last):
  File "/usr/lib/python2.6/threading.py", line 532, in __bootstrap_inner
    self.run()
  File "/usr/lib/python2.6/threading.py", line 736, in run
    self.function(*self.args, **self.kwargs)
TypeError: 'NoneType' object is not callable

Exception in thread Thread-195:
Traceback (most recent call last):
  File "/usr/lib/python2.6/threading.py", line 532, in __bootstrap_inner
    self.run()
  File "/usr/lib/python2.6/threading.py", line 736, in run
    self.function(*self.args, **self.kwargs)
TypeError: 'NoneType' object is not callable

Exception in thread Thread-198:
Traceback (most recent call last):
  File "/usr/lib/python2.6/threading.py", line 532, in __bootstrap_inner
    self.run()
  File "/usr/lib/python2.6/threading.py", line 736, in run
    self.function(*self.args, **self.kwargs)
TypeError: 'NoneType' object is not callable

Exception in thread Thread-199:
Traceback (most recent call last):
  File "/usr/lib/python2.6/threading.py", line 532, in __bootstrap_inner
    self.run()
  File "/usr/lib/python2.6/threading.py", line 736, in run
    self.function(*self.args, **self.kwargs)
TypeError: 'NoneType' object is not callable

Exception in thread Thread-200:
Traceback (most recent call last):
  File "/usr/lib/python2.6/threading.py", line 532, in __bootstrap_inner
    self.run()
  File "/usr/lib/python2.6/threading.py", line 736, in run
    self.function(*self.args, **self.kwargs)
TypeError: 'NoneType' object is not callable

Exception in thread Thread-201:
Traceback (most recent call last):
  File "/usr/lib/python2.6/threading.py", line 532, in __bootstrap_inner
    self.run()
  File "/usr/lib/python2.6/threading.py", line 736, in run
    self.function(*self.args, **self.kwargs)
TypeError: 'NoneType' object is not callable

Exception in thread Thread-202:
Traceback (most recent call last):
  File "/usr/lib/python2.6/threading.py", line 532, in __bootstrap_inner
    self.run()
  File "/usr/lib/python2.6/threading.py", line 736, in run
    self.function(*self.args, **self.kwargs)
TypeError: 'NoneType' object is not callable

Exception in thread Thread-203:
Traceback (most recent call last):
  File "/usr/lib/python2.6/threading.py", line 532, in __bootstrap_inner
    self.run()
  File "/usr/lib/python2.6/threading.py", line 736, in run
    self.function(*self.args, **self.kwargs)
TypeError: 'NoneType' object is not callable

Exception in thread Thread-206:
Traceback (most recent call last):
  File "/usr/lib/python2.6/threading.py", line 532, in __bootstrap_inner
    self.run()
  File "/usr/lib/python2.6/threading.py", line 736, in run
    self.function(*self.args, **self.kwargs)
TypeError: 'NoneType' object is not callable

Exception in thread Thread-205:
Traceback (most recent call last):
  File "/usr/lib/python2.6/threading.py", line 532, in __bootstrap_inner
    self.run()
  File "/usr/lib/python2.6/threading.py", line 736, in run
    self.function(*self.args, **self.kwargs)
TypeError: 'NoneType' object is not callable

Exception in thread Thread-204:
Traceback (most recent call last):
  File "/usr/lib/python2.6/threading.py", line 532, in __bootstrap_inner
    self.run()
  File "/usr/lib/python2.6/threading.py", line 736, in run
    self.function(*self.args, **self.kwargs)
TypeError: 'NoneType' object is not callable

Exception in thread Thread-190:
Traceback (most recent call last):
  File "/usr/lib/python2.6/threading.py", line 532, in __bootstrap_inner
    self.run()
  File "/usr/lib/python2.6/threading.py", line 736, in run
    self.function(*self.args, **self.kwargs)
TypeError: 'NoneType' object is not callable

Exception in thread Thread-210:
Traceback (most recent call last):
  File "/usr/lib/python2.6/threading.py", line 532, in __bootstrap_inner
    self.run()
  File "/usr/lib/python2.6/threading.py", line 736, in run
    self.function(*self.args, **self.kwargs)
TypeError: 'NoneType' object is not callable

Exception in thread Thread-207:
Traceback (most recent call last):
  File "/usr/lib/python2.6/threading.py", line 532, in __bootstrap_inner
    self.run()
  File "/usr/lib/python2.6/threading.py", line 736, in run
    self.function(*self.args, **self.kwargs)
TypeError: 'NoneType' object is not callable

Exception in thread Thread-209:
Traceback (most recent call last):
  File "/usr/lib/python2.6/threading.py", line 532, in __bootstrap_inner
    self.run()
  File "/usr/lib/python2.6/threading.py", line 736, in run
    self.function(*self.args, **self.kwargs)
TypeError: 'NoneType' object is not callable

Exception in thread Thread-211:
Traceback (most recent call last):
  File "/usr/lib/python2.6/threading.py", line 532, in __bootstrap_inner
    self.run()
  File "/usr/lib/python2.6/threading.py", line 736, in run
    self.function(*self.args, **self.kwargs)
TypeError: 'NoneType' object is not callable

Exception in thread Thread-213:
Traceback (most recent call last):
  File "/usr/lib/python2.6/threading.py", line 532, in __bootstrap_inner
    self.run()
  File "/usr/lib/python2.6/threading.py", line 736, in run
    self.function(*self.args, **self.kwargs)
TypeError: 'NoneType' object is not callable

Exception in thread Thread-216:
Traceback (most recent call last):
  File "/usr/lib/python2.6/threading.py", line 532, in __bootstrap_inner
    self.run()
  File "/usr/lib/python2.6/threading.py", line 736, in run
    self.function(*self.args, **self.kwargs)
TypeError: 'NoneType' object is not callable

Exception in thread Thread-217:
Traceback (most recent call last):
  File "/usr/lib/python2.6/threading.py", line 532, in __bootstrap_inner
    self.run()
  File "/usr/lib/python2.6/threading.py", line 736, in run
    self.function(*self.args, **self.kwargs)
TypeError: 'NoneType' object is not callable

Exception in thread Thread-215:
Traceback (most recent call last):
  File "/usr/lib/python2.6/threading.py", line 532, in __bootstrap_inner
    self.run()
  File "/usr/lib/python2.6/threading.py", line 736, in run
    self.function(*self.args, **self.kwargs)
TypeError: 'NoneType' object is not callable

Exception in thread Thread-212:
Traceback (most recent call last):
  File "/usr/lib/python2.6/threading.py", line 532, in __bootstrap_inner
    self.run()
  File "/usr/lib/python2.6/threading.py", line 736, in run
    self.function(*self.args, **self.kwargs)
TypeError: 'NoneType' object is not callable

Exception in thread Thread-219:
Traceback (most recent call last):
  File "/usr/lib/python2.6/threading.py", line 532, in __bootstrap_inner
    self.run()
  File "/usr/lib/python2.6/threading.py", line 736, in run
    self.function(*self.args, **self.kwargs)
TypeError: 'NoneType' object is not callable

Exception in thread Thread-208:
Traceback (most recent call last):
  File "/usr/lib/python2.6/threading.py", line 532, in __bootstrap_inner
    self.run()
  File "/usr/lib/python2.6/threading.py", line 736, in run
    self.function(*self.args, **self.kwargs)
TypeError: 'NoneType' object is not callable

Exception in thread Thread-214:
Traceback (most recent call last):
  File "/usr/lib/python2.6/threading.py", line 532, in __bootstrap_inner
    self.run()
  File "/usr/lib/python2.6/threading.py", line 736, in run
    self.function(*self.args, **self.kwargs)
TypeError: 'NoneType' object is not callable

Exception in thread Thread-220:
Traceback (most recent call last):
  File "/usr/lib/python2.6/threading.py", line 532, in __bootstrap_inner
    self.run()
  File "/usr/lib/python2.6/threading.py", line 736, in run
    self.function(*self.args, **self.kwargs)
TypeError: 'NoneType' object is not callable

Exception in thread Thread-221:
Traceback (most recent call last):
  File "/usr/lib/python2.6/threading.py", line 532, in __bootstrap_inner
    self.run()
  File "/usr/lib/python2.6/threading.py", line 736, in run
    self.function(*self.args, **self.kwargs)
TypeError: 'NoneType' object is not callable

Exception in thread Thread-222:
Traceback (most recent call last):
  File "/usr/lib/python2.6/threading.py", line 532, in __bootstrap_inner
    self.run()
  File "/usr/lib/python2.6/threading.py", line 736, in run
    self.function(*self.args, **self.kwargs)
TypeError: 'NoneType' object is not callable

Exception in thread Thread-218:
Traceback (most recent call last):
  File "/usr/lib/python2.6/threading.py", line 532, in __bootstrap_inner
    self.run()
  File "/usr/lib/python2.6/threading.py", line 736, in run
    self.function(*self.args, **self.kwargs)
TypeError: 'NoneType' object is not callable

Exception in thread Thread-224:
Traceback (most recent call last):
  File "/usr/lib/python2.6/threading.py", line 532, in __bootstrap_inner
    self.run()
  File "/usr/lib/python2.6/threading.py", line 736, in run
    self.function(*self.args, **self.kwargs)
TypeError: 'NoneType' object is not callable

Exception in thread Thread-227:
Traceback (most recent call last):
  File "/usr/lib/python2.6/threading.py", line 532, in __bootstrap_inner
    self.run()
  File "/usr/lib/python2.6/threading.py", line 736, in run
    self.function(*self.args, **self.kwargs)
TypeError: 'NoneType' object is not callable

Exception in thread Thread-225:
Traceback (most recent call last):
  File "/usr/lib/python2.6/threading.py", line 532, in __bootstrap_inner
    self.run()
  File "/usr/lib/python2.6/threading.py", line 736, in run
    self.function(*self.args, **self.kwargs)
TypeError: 'NoneType' object is not callable

Exception in thread Thread-223:
Traceback (most recent call last):
  File "/usr/lib/python2.6/threading.py", line 532, in __bootstrap_inner
    self.run()
  File "/usr/lib/python2.6/threading.py", line 736, in run
    self.function(*self.args, **self.kwargs)
TypeError: 'NoneType' object is not callable

Exception in thread Thread-226:
Traceback (most recent call last):
  File "/usr/lib/python2.6/threading.py", line 532, in __bootstrap_inner
    self.run()
  File "/usr/lib/python2.6/threading.py", line 736, in run
    self.function(*self.args, **self.kwargs)
TypeError: 'NoneType' object is not callable

Exception in thread Thread-230:
Traceback (most recent call last):
  File "/usr/lib/python2.6/threading.py", line 532, in __bootstrap_inner
    self.run()
  File "/usr/lib/python2.6/threading.py", line 736, in run
    self.function(*self.args, **self.kwargs)
TypeError: 'NoneType' object is not callable

Exception in thread Thread-228:
Traceback (most recent call last):
  File "/usr/lib/python2.6/threading.py", line 532, in __bootstrap_inner
    self.run()
  File "/usr/lib/python2.6/threading.py", line 736, in run
    self.function(*self.args, **self.kwargs)
TypeError: 'NoneType' object is not callable

Exception in thread Thread-231:
Traceback (most recent call last):
  File "/usr/lib/python2.6/threading.py", line 532, in __bootstrap_inner
    self.run()
  File "/usr/lib/python2.6/threading.py", line 736, in run
    self.function(*self.args, **self.kwargs)
TypeError: 'NoneType' object is not callable

Exception in thread Thread-234:
Traceback (most recent call last):
  File "/usr/lib/python2.6/threading.py", line 532, in __bootstrap_inner
    self.run()
  File "/usr/lib/python2.6/threading.py", line 736, in run
    self.function(*self.args, **self.kwargs)
TypeError: 'NoneType' object is not callable

Exception in thread Thread-232:
Traceback (most recent call last):
  File "/usr/lib/python2.6/threading.py", line 532, in __bootstrap_inner
    self.run()
  File "/usr/lib/python2.6/threading.py", line 736, in run
    self.function(*self.args, **self.kwargs)
TypeError: 'NoneType' object is not callable

Exception in thread Thread-233:
Traceback (most recent call last):
  File "/usr/lib/python2.6/threading.py", line 532, in __bootstrap_inner
    self.run()
  File "/usr/lib/python2.6/threading.py", line 736, in run
    self.function(*self.args, **self.kwargs)
TypeError: 'NoneType' object is not callable

Exception in thread Thread-229:
Traceback (most recent call last):
  File "/usr/lib/python2.6/threading.py", line 532, in __bootstrap_inner
    self.run()
  File "/usr/lib/python2.6/threading.py", line 736, in run
    self.function(*self.args, **self.kwargs)
TypeError: 'NoneType' object is not callable

Exception in thread Thread-236:
Traceback (most recent call last):
  File "/usr/lib/python2.6/threading.py", line 532, in __bootstrap_inner
    self.run()
  File "/usr/lib/python2.6/threading.py", line 736, in run
    self.function(*self.args, **self.kwargs)
TypeError: 'NoneType' object is not callable

Exception in thread Thread-235:
Traceback (most recent call last):
  File "/usr/lib/python2.6/threading.py", line 532, in __bootstrap_inner
    self.run()
  File "/usr/lib/python2.6/threading.py", line 736, in run
    self.function(*self.args, **self.kwargs)
TypeError: 'NoneType' object is not callable

Exception in thread Thread-239:
Traceback (most recent call last):
  File "/usr/lib/python2.6/threading.py", line 532, in __bootstrap_inner
    self.run()
  File "/usr/lib/python2.6/threading.py", line 736, in run
    self.function(*self.args, **self.kwargs)
TypeError: 'NoneType' object is not callable

Exception in thread Thread-237:
Traceback (most recent call last):
  File "/usr/lib/python2.6/threading.py", line 532, in __bootstrap_inner
    self.run()
  File "/usr/lib/python2.6/threading.py", line 736, in run
    self.function(*self.args, **self.kwargs)
TypeError: 'NoneType' object is not callable

Exception in thread Thread-238:
Traceback (most recent call last):
  File "/usr/lib/python2.6/threading.py", line 532, in __bootstrap_inner
    self.run()
  File "/usr/lib/python2.6/threading.py", line 736, in run
    self.function(*self.args, **self.kwargs)
TypeError: 'NoneType' object is not callable

Exception in thread Thread-241:
Traceback (most recent call last):
  File "/usr/lib/python2.6/threading.py", line 532, in __bootstrap_inner
    self.run()
  File "/usr/lib/python2.6/threading.py", line 736, in run
    self.function(*self.args, **self.kwargs)
TypeError: 'NoneType' object is not callable

Exception in thread Thread-240:
Traceback (most recent call last):
  File "/usr/lib/python2.6/threading.py", line 532, in __bootstrap_inner
    self.run()
  File "/usr/lib/python2.6/threading.py", line 736, in run
    self.function(*self.args, **self.kwargs)
TypeError: 'NoneType' object is not callable

Exception in thread Thread-243:
Traceback (most recent call last):
  File "/usr/lib/python2.6/threading.py", line 532, in __bootstrap_inner
    self.run()
  File "/usr/lib/python2.6/threading.py", line 736, in run
    self.function(*self.args, **self.kwargs)
TypeError: 'NoneType' object is not callable

Exception in thread Thread-242:
Traceback (most recent call last):
  File "/usr/lib/python2.6/threading.py", line 532, in __bootstrap_inner
    self.run()
  File "/usr/lib/python2.6/threading.py", line 736, in run
    self.function(*self.args, **self.kwargs)
TypeError: 'NoneType' object is not callable

Exception in thread Thread-244:
Traceback (most recent call last):
  File "/usr/lib/python2.6/threading.py", line 532, in __bootstrap_inner
    self.run()
  File "/usr/lib/python2.6/threading.py", line 736, in run
    self.function(*self.args, **self.kwargs)
TypeError: 'NoneType' object is not callable

Exception in thread Thread-246:
Traceback (most recent call last):
  File "/usr/lib/python2.6/threading.py", line 532, in __bootstrap_inner
    self.run()
  File "/usr/lib/python2.6/threading.py", line 736, in run
    self.function(*self.args, **self.kwargs)
TypeError: 'NoneType' object is not callable

Exception in thread Thread-248:
Traceback (most recent call last):
  File "/usr/lib/python2.6/threading.py", line 532, in __bootstrap_inner
    self.run()
  File "/usr/lib/python2.6/threading.py", line 736, in run
    self.function(*self.args, **self.kwargs)
TypeError: 'NoneType' object is not callable

Exception in thread Thread-245:
Traceback (most recent call last):
  File "/usr/lib/python2.6/threading.py", line 532, in __bootstrap_inner
    self.run()
  File "/usr/lib/python2.6/threading.py", line 736, in run
    self.function(*self.args, **self.kwargs)
TypeError: 'NoneType' object is not callable

Exception in thread Thread-247:
Traceback (most recent call last):
  File "/usr/lib/python2.6/threading.py", line 532, in __bootstrap_inner
    self.run()
  File "/usr/lib/python2.6/threading.py", line 736, in run
    self.function(*self.args, **self.kwargs)
TypeError: 'NoneType' object is not callable

Exception in thread Thread-249:
Traceback (most recent call last):
  File "/usr/lib/python2.6/threading.py", line 532, in __bootstrap_inner
    self.run()
  File "/usr/lib/python2.6/threading.py", line 736, in run
    self.function(*self.args, **self.kwargs)
TypeError: 'NoneType' object is not callable

Exception in thread Thread-250:
Traceback (most recent call last):
  File "/usr/lib/python2.6/threading.py", line 532, in __bootstrap_inner
    self.run()
  File "/usr/lib/python2.6/threading.py", line 736, in run
    self.function(*self.args, **self.kwargs)
TypeError: 'NoneType' object is not callable

Exception in thread Thread-253:
Traceback (most recent call last):
  File "/usr/lib/python2.6/threading.py", line 532, in __bootstrap_inner
    self.run()
  File "/usr/lib/python2.6/threading.py", line 736, in run
    self.function(*self.args, **self.kwargs)
TypeError: 'NoneType' object is not callable

Exception in thread Thread-251:
Traceback (most recent call last):
  File "/usr/lib/python2.6/threading.py", line 532, in __bootstrap_inner
    self.run()
  File "/usr/lib/python2.6/threading.py", line 736, in run
    self.function(*self.args, **self.kwargs)
TypeError: 'NoneType' object is not callable

Exception in thread Thread-252:
Traceback (most recent call last):
  File "/usr/lib/python2.6/threading.py", line 532, in __bootstrap_inner
    self.run()
  File "/usr/lib/python2.6/threading.py", line 736, in run
    self.function(*self.args, **self.kwargs)
TypeError: 'NoneType' object is not callable

Exception in thread Thread-255:
Traceback (most recent call last):
  File "/usr/lib/python2.6/threading.py", line 532, in __bootstrap_inner
    self.run()
  File "/usr/lib/python2.6/threading.py", line 736, in run
    self.function(*self.args, **self.kwargs)
TypeError: 'NoneType' object is not callable

Exception in thread Thread-256:
Traceback (most recent call last):
  File "/usr/lib/python2.6/threading.py", line 532, in __bootstrap_inner
    self.run()
  File "/usr/lib/python2.6/threading.py", line 736, in run
    self.function(*self.args, **self.kwargs)
TypeError: 'NoneType' object is not callable

Exception in thread Thread-258:
Traceback (most recent call last):
  File "/usr/lib/python2.6/threading.py", line 532, in __bootstrap_inner
    self.run()
  File "/usr/lib/python2.6/threading.py", line 736, in run
    self.function(*self.args, **self.kwargs)
TypeError: 'NoneType' object is not callable

Exception in thread Thread-257:
Traceback (most recent call last):
  File "/usr/lib/python2.6/threading.py", line 532, in __bootstrap_inner
    self.run()
  File "/usr/lib/python2.6/threading.py", line 736, in run
    self.function(*self.args, **self.kwargs)
TypeError: 'NoneType' object is not callable

Exception in thread Thread-254:
Traceback (most recent call last):
  File "/usr/lib/python2.6/threading.py", line 532, in __bootstrap_inner
    self.run()
  File "/usr/lib/python2.6/threading.py", line 736, in run
    self.function(*self.args, **self.kwargs)
TypeError: 'NoneType' object is not callable

Exception in thread Thread-259:
Traceback (most recent call last):
  File "/usr/lib/python2.6/threading.py", line 532, in __bootstrap_inner
    self.run()
  File "/usr/lib/python2.6/threading.py", line 736, in run
    self.function(*self.args, **self.kwargs)
TypeError: 'NoneType' object is not callable

Exception in thread Thread-261:
Traceback (most recent call last):
  File "/usr/lib/python2.6/threading.py", line 532, in __bootstrap_inner
    self.run()
  File "/usr/lib/python2.6/threading.py", line 736, in run
    self.function(*self.args, **self.kwargs)
TypeError: 'NoneType' object is not callable

Exception in thread Thread-262:
Traceback (most recent call last):
  File "/usr/lib/python2.6/threading.py", line 532, in __bootstrap_inner
    self.run()
  File "/usr/lib/python2.6/threading.py", line 736, in run
    self.function(*self.args, **self.kwargs)
TypeError: 'NoneType' object is not callable

Exception in thread Thread-260:
Traceback (most recent call last):
  File "/usr/lib/python2.6/threading.py", line 532, in __bootstrap_inner
    self.run()
  File "/usr/lib/python2.6/threading.py", line 736, in run
    self.function(*self.args, **self.kwargs)
TypeError: 'NoneType' object is not callable

Exception in thread Thread-263:
Traceback (most recent call last):
  File "/usr/lib/python2.6/threading.py", line 532, in __bootstrap_inner
    self.run()
  File "/usr/lib/python2.6/threading.py", line 736, in run
    self.function(*self.args, **self.kwargs)
TypeError: 'NoneType' object is not callable

Exception in thread Thread-264:
Traceback (most recent call last):
  File "/usr/lib/python2.6/threading.py", line 532, in __bootstrap_inner
    self.run()
  File "/usr/lib/python2.6/threading.py", line 736, in run
    self.function(*self.args, **self.kwargs)
TypeError: 'NoneType' object is not callable

Exception in thread Thread-265:
Traceback (most recent call last):
  File "/usr/lib/python2.6/threading.py", line 532, in __bootstrap_inner
    self.run()
  File "/usr/lib/python2.6/threading.py", line 736, in run
    self.function(*self.args, **self.kwargs)
TypeError: 'NoneType' object is not callable

Exception in thread Thread-266:
Traceback (most recent call last):
  File "/usr/lib/python2.6/threading.py", line 532, in __bootstrap_inner
    self.run()
  File "/usr/lib/python2.6/threading.py", line 736, in run
    self.function(*self.args, **self.kwargs)
TypeError: 'NoneType' object is not callable

Exception in thread Thread-267:
Traceback (most recent call last):
  File "/usr/lib/python2.6/threading.py", line 532, in __bootstrap_inner
    self.run()
  File "/usr/lib/python2.6/threading.py", line 736, in run
    self.function(*self.args, **self.kwargs)
TypeError: 'NoneType' object is not callable

Exception in thread Thread-268:
Traceback (most recent call last):
  File "/usr/lib/python2.6/threading.py", line 532, in __bootstrap_inner
    self.run()
  File "/usr/lib/python2.6/threading.py", line 736, in run
    self.function(*self.args, **self.kwargs)
TypeError: 'NoneType' object is not callable

Exception in thread Thread-270:
Traceback (most recent call last):
  File "/usr/lib/python2.6/threading.py", line 532, in __bootstrap_inner
    self.run()
  File "/usr/lib/python2.6/threading.py", line 736, in run
    self.function(*self.args, **self.kwargs)
TypeError: 'NoneType' object is not callable

Exception in thread Thread-269:
Traceback (most recent call last):
  File "/usr/lib/python2.6/threading.py", line 532, in __bootstrap_inner
    self.run()
  File "/usr/lib/python2.6/threading.py", line 736, in run
    self.function(*self.args, **self.kwargs)
TypeError: 'NoneType' object is not callable

Exception in thread Thread-271:
Traceback (most recent call last):
  File "/usr/lib/python2.6/threading.py", line 532, in __bootstrap_inner
    self.run()
  File "/usr/lib/python2.6/threading.py", line 736, in run
    self.function(*self.args, **self.kwargs)
TypeError: 'NoneType' object is not callable

Exception in thread Thread-272:
Traceback (most recent call last):
  File "/usr/lib/python2.6/threading.py", line 532, in __bootstrap_inner
    self.run()
  File "/usr/lib/python2.6/threading.py", line 736, in run
    self.function(*self.args, **self.kwargs)
TypeError: 'NoneType' object is not callable

Exception in thread Thread-273:
Traceback (most recent call last):
  File "/usr/lib/python2.6/threading.py", line 532, in __bootstrap_inner
    self.run()
  File "/usr/lib/python2.6/threading.py", line 736, in run
    self.function(*self.args, **self.kwargs)
TypeError: 'NoneType' object is not callable

Exception in thread Thread-275:
Traceback (most recent call last):
  File "/usr/lib/python2.6/threading.py", line 532, in __bootstrap_inner
    self.run()
  File "/usr/lib/python2.6/threading.py", line 736, in run
    self.function(*self.args, **self.kwargs)
TypeError: 'NoneType' object is not callable

Exception in thread Thread-274:
Traceback (most recent call last):
  File "/usr/lib/python2.6/threading.py", line 532, in __bootstrap_inner
    self.run()
  File "/usr/lib/python2.6/threading.py", line 736, in run
    self.function(*self.args, **self.kwargs)
TypeError: 'NoneType' object is not callable

Exception in thread Thread-276:
Traceback (most recent call last):
  File "/usr/lib/python2.6/threading.py", line 532, in __bootstrap_inner
    self.run()
  File "/usr/lib/python2.6/threading.py", line 736, in run
    self.function(*self.args, **self.kwargs)
TypeError: 'NoneType' object is not callable

Exception in thread Thread-277:
Traceback (most recent call last):
  File "/usr/lib/python2.6/threading.py", line 532, in __bootstrap_inner
    self.run()
  File "/usr/lib/python2.6/threading.py", line 736, in run
    self.function(*self.args, **self.kwargs)
TypeError: 'NoneType' object is not callable

Exception in thread Thread-279:
Traceback (most recent call last):
  File "/usr/lib/python2.6/threading.py", line 532, in __bootstrap_inner
    self.run()
  File "/usr/lib/python2.6/threading.py", line 736, in run
    self.function(*self.args, **self.kwargs)
TypeError: 'NoneType' object is not callable

Exception in thread Thread-278:
Traceback (most recent call last):
  File "/usr/lib/python2.6/threading.py", line 532, in __bootstrap_inner
    self.run()
  File "/usr/lib/python2.6/threading.py", line 736, in run
    self.function(*self.args, **self.kwargs)
TypeError: 'NoneType' object is not callable

Exception in thread Thread-280:
Traceback (most recent call last):
  File "/usr/lib/python2.6/threading.py", line 532, in __bootstrap_inner
    self.run()
  File "/usr/lib/python2.6/threading.py", line 736, in run
    self.function(*self.args, **self.kwargs)
TypeError: 'NoneType' object is not callable

Exception in thread Thread-281:
Traceback (most recent call last):
  File "/usr/lib/python2.6/threading.py", line 532, in __bootstrap_inner
    self.run()
  File "/usr/lib/python2.6/threading.py", line 736, in run
    self.function(*self.args, **self.kwargs)
TypeError: 'NoneType' object is not callable

Exception in thread Thread-282:
Traceback (most recent call last):
  File "/usr/lib/python2.6/threading.py", line 532, in __bootstrap_inner
    self.run()
  File "/usr/lib/python2.6/threading.py", line 736, in run
    self.function(*self.args, **self.kwargs)
TypeError: 'NoneType' object is not callable

Exception in thread Thread-284:
Traceback (most recent call last):
  File "/usr/lib/python2.6/threading.py", line 532, in __bootstrap_inner
    self.run()
  File "/usr/lib/python2.6/threading.py", line 736, in run
    self.function(*self.args, **self.kwargs)
TypeError: 'NoneType' object is not callable

Exception in thread Thread-283:
Traceback (most recent call last):
  File "/usr/lib/python2.6/threading.py", line 532, in __bootstrap_inner
    self.run()
  File "/usr/lib/python2.6/threading.py", line 736, in run
    self.function(*self.args, **self.kwargs)
TypeError: 'NoneType' object is not callable

Exception in thread Thread-286:
Traceback (most recent call last):
  File "/usr/lib/python2.6/threading.py", line 532, in __bootstrap_inner
    self.run()
  File "/usr/lib/python2.6/threading.py", line 736, in run
    self.function(*self.args, **self.kwargs)
TypeError: 'NoneType' object is not callable

Exception in thread Thread-285:
Traceback (most recent call last):
  File "/usr/lib/python2.6/threading.py", line 532, in __bootstrap_inner
    self.run()
  File "/usr/lib/python2.6/threading.py", line 736, in run
    self.function(*self.args, **self.kwargs)
TypeError: 'NoneType' object is not callable

Exception in thread Thread-287:
Traceback (most recent call last):
  File "/usr/lib/python2.6/threading.py", line 532, in __bootstrap_inner
    self.run()
  File "/usr/lib/python2.6/threading.py", line 736, in run
    self.function(*self.args, **self.kwargs)
TypeError: 'NoneType' object is not callable

Exception in thread Thread-289:
Traceback (most recent call last):
  File "/usr/lib/python2.6/threading.py", line 532, in __bootstrap_inner
    self.run()
  File "/usr/lib/python2.6/threading.py", line 736, in run
    self.function(*self.args, **self.kwargs)
TypeError: 'NoneType' object is not callable

Exception in thread Thread-288:
Traceback (most recent call last):
  File "/usr/lib/python2.6/threading.py", line 532, in __bootstrap_inner
    self.run()
  File "/usr/lib/python2.6/threading.py", line 736, in run
    self.function(*self.args, **self.kwargs)
TypeError: 'NoneType' object is not callable

Exception in thread Thread-294:
Traceback (most recent call last):
  File "/usr/lib/python2.6/threading.py", line 532, in __bootstrap_inner
    self.run()
  File "/usr/lib/python2.6/threading.py", line 736, in run
    self.function(*self.args, **self.kwargs)
TypeError: 'NoneType' object is not callable

Exception in thread Thread-293:
Traceback (most recent call last):
  File "/usr/lib/python2.6/threading.py", line 532, in __bootstrap_inner
    self.run()
  File "/usr/lib/python2.6/threading.py", line 736, in run
    self.function(*self.args, **self.kwargs)
TypeError: 'NoneType' object is not callable

Exception in thread Thread-292:
Traceback (most recent call last):
  File "/usr/lib/python2.6/threading.py", line 532, in __bootstrap_inner
    self.run()
  File "/usr/lib/python2.6/threading.py", line 736, in run
    self.function(*self.args, **self.kwargs)
TypeError: 'NoneType' object is not callable

Exception in thread Thread-291:
Traceback (most recent call last):
  File "/usr/lib/python2.6/threading.py", line 532, in __bootstrap_inner
    self.run()
  File "/usr/lib/python2.6/threading.py", line 736, in run
    self.function(*self.args, **self.kwargs)
TypeError: 'NoneType' object is not callable

Exception in thread Thread-290:
Traceback (most recent call last):
  File "/usr/lib/python2.6/threading.py", line 532, in __bootstrap_inner
    self.run()
  File "/usr/lib/python2.6/threading.py", line 736, in run
    self.function(*self.args, **self.kwargs)
TypeError: 'NoneType' object is not callable

Exception in thread Thread-295:
Traceback (most recent call last):
  File "/usr/lib/python2.6/threading.py", line 532, in __bootstrap_inner
    self.run()
  File "/usr/lib/python2.6/threading.py", line 736, in run
    self.function(*self.args, **self.kwargs)
TypeError: 'NoneType' object is not callable

